<?xml version="1.0" encoding="utf-8"?>
<!-- This URDF was automatically created by SolidWorks to URDF Exporter! Originally created by Stephen Brawner (brawner@gmail.com) 
     Commit Version: 1.6.0-4-g7f85cfe  Build Version: 1.6.7995.38578
     For more information, please see http://wiki.ros.org/sw_urdf_exporter -->
<robot
  name="++URDF_2.0">
  <link
    name="base_link">
    <inertial>
      <origin
        xyz="-1.11022302462516E-16 -0.00302360042075001 -5.55111512312578E-17"
        rpy="0 0 0" />
      <mass
        value="0.315535261055246" />
      <inertia
        ixx="5.55978934043807E-05"
        ixy="-2.23968175003346E-21"
        ixz="-2.00347430591937E-21"
        iyy="0.000227649084365836"
        iyz="-9.07401797022921E-21"
        izz="0.000187249617089345" />
    </inertial>
    <visual>
      <origin
        xyz="0 0 0"
        rpy="0 0 0" />
      <geometry>
        <mesh
          filename="package://++URDF_2.0/meshes/base_link.STL" />
      </geometry>
      <material
        name="">
        <color
          rgba="1 1 1 1" />
      </material>
    </visual>
    <collision>
      <origin
        xyz="0 0 0"
        rpy="0 0 0" />
      <geometry>
        <mesh
          filename="package://++URDF_2.0/meshes/base_link.STL" />
      </geometry>
    </collision>
  </link>
  <link
    name="fl_hip">
    <inertial>
      <origin
        xyz="0.0272971333033659 1.75159621585985E-05 0.00247430441137858"
        rpy="0 0 0" />
      <mass
        value="0.0474176719706317" />
      <inertia
        ixx="2.17411039399833E-05"
        ixy="-7.54915453758999E-09"
        ixz="-3.88620482540354E-07"
        iyy="3.26033730626776E-05"
        iyz="1.65166872304556E-07"
        izz="4.26370569453741E-05" />
    </inertial>
    <visual>
      <origin
        xyz="0 0 0"
        rpy="0 0 0" />
      <geometry>
        <mesh
          filename="package://++URDF_2.0/meshes/fl_hip.STL" />
      </geometry>
      <material
        name="">
        <color
          rgba="1 1 1 1" />
      </material>
    </visual>
    <collision>
      <origin
        xyz="0 0 0"
        rpy="0 0 0" />
      <geometry>
        <mesh
          filename="package://++URDF_2.0/meshes/fl_hip.STL" />
      </geometry>
    </collision>
  </link>
  <joint
    name="fl_hip"
    type="continuous">
    <origin
      xyz="0.0984 -0.00302922105364484 -0.0606811932633947"
      rpy="0 0 0" />
    <parent
      link="base_link" />
    <child
      link="fl_hip" />
    <axis
      xyz="1 0 0" />
  </joint>
  <link
    name="fl_top">
    <inertial>
      <origin
        xyz="-0.0327093590748004 -0.0129114746104738 0.00626100034714228"
        rpy="0 0 0" />
      <mass
        value="0.139807399014711" />
      <inertia
        ixx="3.65926535985209E-05"
        ixy="-4.86382412840218E-05"
        ixz="1.9486191771268E-06"
        iyy="0.000125513458229608"
        iyz="1.26374835194812E-06"
        izz="0.000148862975841844" />
    </inertial>
    <visual>
      <origin
        xyz="0 0 0"
        rpy="0 0 0" />
      <geometry>
        <mesh
          filename="package://++URDF_2.0/meshes/fl_top.STL" />
      </geometry>
      <material
        name="">
        <color
          rgba="1 1 1 1" />
      </material>
    </visual>
    <collision>
      <origin
        xyz="0 0 0"
        rpy="0 0 0" />
      <geometry>
        <mesh
          filename="package://++URDF_2.0/meshes/fl_top.STL" />
      </geometry>
    </collision>
  </link>
  <joint
    name="fl_top"
    type="continuous">
    <origin
      xyz="0.03859999999999 -0.0114831518350568 -0.0322319286412233"
      rpy="0 0 0" />
    <parent
      link="fl_hip" />
    <child
      link="fl_top" />
    <axis
      xyz="0 -0.0149500362179808 -0.999888241963611" />
  </joint>
  <link
    name="fl_bottom">
    <inertial>
      <origin
        xyz="0.078482158861255 -0.0448672466577361 0.00348748963952544"
        rpy="0 0 0" />
      <mass
        value="0.0474313349742766" />
      <inertia
        ixx="2.61536457002355E-05"
        ixy="3.60251937346389E-05"
        ixz="-5.38425820651276E-07"
        iyy="6.08830489314348E-05"
        iyz="3.54056592344967E-07"
        izz="8.45670496666924E-05" />
    </inertial>
    <visual>
      <origin
        xyz="0 0 0"
        rpy="0 0 0" />
      <geometry>
        <mesh
          filename="package://++URDF_2.0/meshes/fl_bottom.STL" />
      </geometry>
      <material
        name="">
        <color
          rgba="1 1 1 1" />
      </material>
    </visual>
    <collision>
      <origin
        xyz="0 0 0"
        rpy="0 0 0" />
      <geometry>
        <mesh
          filename="package://++URDF_2.0/meshes/fl_bottom.STL" />
      </geometry>
    </collision>
  </link>
  <joint
    name="fl_bottom"
    type="continuous">
    <origin
      xyz="-0.121320784830054 -0.0723866953679673 -0.0135693327645339"
      rpy="0 0 0" />
    <parent
      link="fl_top" />
    <child
      link="fl_bottom" />
    <axis
      xyz="0 -0.0149500362179846 -0.999888241963611" />
  </joint>
  <link
    name="fr_hip">
    <inertial>
      <origin
        xyz="0.027297131982034 9.90275998717094E-05 -0.00247238563061045"
        rpy="0 0 0" />
      <mass
        value="0.0474176723475861" />
      <inertia
        ixx="2.17411062531901E-05"
        ixy="-1.07632885592903E-08"
        ixz="3.88545769681229E-07"
        iyy="3.26100851697043E-05"
        iyz="-3.07652923389535E-07"
        izz="4.26303515792848E-05" />
    </inertial>
    <visual>
      <origin
        xyz="0 0 0"
        rpy="0 0 0" />
      <geometry>
        <mesh
          filename="package://++URDF_2.0/meshes/fr_hip.STL" />
      </geometry>
      <material
        name="">
        <color
          rgba="1 1 1 1" />
      </material>
    </visual>
    <collision>
      <origin
        xyz="0 0 0"
        rpy="0 0 0" />
      <geometry>
        <mesh
          filename="package://++URDF_2.0/meshes/fr_hip.STL" />
      </geometry>
    </collision>
  </link>
  <joint
    name="fr_hip"
    type="continuous">
    <origin
      xyz="0.0984 -0.00302922105364489 0.0606811932633948"
      rpy="0 0 0" />
    <parent
      link="base_link" />
    <child
      link="fr_hip" />
    <axis
      xyz="1 0 0" />
  </joint>
  <link
    name="fr_top">
    <inertial>
      <origin
        xyz="-0.0327864495707165 -0.0126313769769459 -0.00647693886353867"
        rpy="0 0 0" />
      <mass
        value="0.139807219355074" />
      <inertia
        ixx="3.60145763368299E-05"
        ixy="-4.80987732569624E-05"
        ixz="-2.77517694329877E-06"
        iyy="0.000126140761129269"
        iyz="-1.63921611186352E-06"
        izz="0.000148813501843454" />
    </inertial>
    <visual>
      <origin
        xyz="0 0 0"
        rpy="0 0 0" />
      <geometry>
        <mesh
          filename="package://++URDF_2.0/meshes/fr_top.STL" />
      </geometry>
      <material
        name="">
        <color
          rgba="1 1 1 1" />
      </material>
    </visual>
    <collision>
      <origin
        xyz="0 0 0"
        rpy="0 0 0" />
      <geometry>
        <mesh
          filename="package://++URDF_2.0/meshes/fr_top.STL" />
      </geometry>
    </collision>
  </link>
  <joint
    name="fr_top"
    type="continuous">
    <origin
      xyz="0.0381 -0.0121363664341451 0.0320262175377635"
      rpy="0 0 0" />
    <parent
      link="fr_hip" />
    <child
      link="fr_top" />
    <axis
      xyz="0 -0.0321638727308679 0.999482608798649" />
  </joint>
  <link
    name="fr_bottom">
    <inertial>
      <origin
        xyz="0.0791469661032436 -0.0433740165808617 -0.0042133669017476"
        rpy="0 0 0" />
      <mass
        value="0.047431300905697" />
      <inertia
        ixx="2.48656407351239E-05"
        ixy="3.53612962863047E-05"
        ixz="1.13817640664229E-06"
        iyy="6.21887613940631E-05"
        iyz="-7.20454050525756E-07"
        izz="8.4548965184245E-05" />
    </inertial>
    <visual>
      <origin
        xyz="0 0 0"
        rpy="0 0 0" />
      <geometry>
        <mesh
          filename="package://++URDF_2.0/meshes/fr_bottom.STL" />
      </geometry>
      <material
        name="">
        <color
          rgba="1 1 1 1" />
      </material>
    </visual>
    <collision>
      <origin
        xyz="0 0 0"
        rpy="0 0 0" />
      <geometry>
        <mesh
          filename="package://++URDF_2.0/meshes/fr_bottom.STL" />
      </geometry>
    </collision>
  </link>
  <joint
    name="fr_bottom"
    type="continuous">
    <origin
      xyz="-0.121749494844511 -0.0718844345331731 0.0123443050311544"
      rpy="0 0 0" />
    <parent
      link="fr_top" />
    <child
      link="fr_bottom" />
    <axis
      xyz="0 -0.0321638727308673 0.999482608798649" />
  </joint>
  <link
    name="br_hip">
    <inertial>
      <origin
        xyz="-0.0272971344226925 -6.43744326411511E-05 -0.00247351850938268"
        rpy="0 0 0" />
      <mass
        value="0.0474176686622597" />
      <inertia
        ixx="2.17411069156437E-05"
        ixy="-5.31705130527036E-09"
        ixz="-3.88657711748629E-07"
        iyy="3.26034343522744E-05"
        iyz="1.67117958442228E-07"
        izz="4.26370068764065E-05" />
    </inertial>
    <visual>
      <origin
        xyz="0 0 0"
        rpy="0 0 0" />
      <geometry>
        <mesh
          filename="package://++URDF_2.0/meshes/br_hip.STL" />
      </geometry>
      <material
        name="">
        <color
          rgba="1 1 1 1" />
      </material>
    </visual>
    <collision>
      <origin
        xyz="0 0 0"
        rpy="0 0 0" />
      <geometry>
        <mesh
          filename="package://++URDF_2.0/meshes/br_hip.STL" />
      </geometry>
    </collision>
  </link>
  <joint
    name="br_hip"
    type="continuous">
    <origin
      xyz="-0.0984 -0.00302922105364489 0.0606811932633947"
      rpy="0 0 0" />
    <parent
      link="base_link" />
    <child
      link="br_hip" />
    <axis
      xyz="-1 0 0" />
  </joint>
  <link
    name="br_top">
    <inertial>
      <origin
        xyz="-0.0331307458806611 -0.0121448427162066 -0.00584779936915039"
        rpy="0 0 0" />
      <mass
        value="0.139807219513831" />
      <inertia
        ixx="3.34135369969368E-05"
        ixy="-4.57757281094289E-05"
        ixz="-4.20400289917179E-07"
        iyy="0.000128634824886818"
        iyz="-5.05556246790766E-07"
        izz="0.000148920477468448" />
    </inertial>
    <visual>
      <origin
        xyz="0 0 0"
        rpy="0 0 0" />
      <geometry>
        <mesh
          filename="package://++URDF_2.0/meshes/br_top.STL" />
      </geometry>
      <material
        name="">
        <color
          rgba="1 1 1 1" />
      </material>
    </visual>
    <collision>
      <origin
        xyz="0 0 0"
        rpy="0 0 0" />
      <geometry>
        <mesh
          filename="package://++URDF_2.0/meshes/br_top.STL" />
      </geometry>
    </collision>
  </link>
  <joint
    name="br_top"
    type="continuous">
    <origin
      xyz="-0.0186000000001146 -0.0104099959720499 0.0325943550920316"
      rpy="0 0 0" />
    <parent
      link="br_hip" />
    <child
      link="br_top" />
    <axis
      xyz="0 0.0181540508072637 0.999835201640394" />
  </joint>
  <link
    name="br_bottom">
    <inertial>
      <origin
        xyz="0.0791720299116837 -0.043485483448343 -0.00202700123300074"
        rpy="0 0 0" />
      <mass
        value="0.0474313351974432" />
      <inertia
        ixx="2.48249541491992E-05"
        ixy="3.53523648270132E-05"
        ixz="-6.41679591763938E-07"
        iyy="6.22138157655498E-05"
        iyz="4.05829964915507E-07"
        izz="8.45649759822487E-05" />
    </inertial>
    <visual>
      <origin
        xyz="0 0 0"
        rpy="0 0 0" />
      <geometry>
        <mesh
          filename="package://++URDF_2.0/meshes/br_bottom.STL" />
      </geometry>
      <material
        name="">
        <color
          rgba="1 1 1 1" />
      </material>
    </visual>
    <collision>
      <origin
        xyz="0 0 0"
        rpy="0 0 0" />
      <geometry>
        <mesh
          filename="package://++URDF_2.0/meshes/br_bottom.STL" />
      </geometry>
    </collision>
  </link>
  <joint
    name="br_bottom"
    type="continuous">
    <origin
      xyz="-0.123680759792053 -0.0677753112514966 0.0158830139385805"
      rpy="0 0 0" />
    <parent
      link="br_top" />
    <child
      link="br_bottom" />
    <axis
      xyz="0 0.0181540508072629 0.999835201640394" />
  </joint>
  <link
    name="bl_hip">
    <inertial>
      <origin
        xyz="-0.0272971324067885 -3.03826091760384E-05 0.00247418544860611"
        rpy="0 0 0" />
      <mass
        value="0.0474176737292141" />
      <inertia
        ixx="2.17411030263018E-05"
        ixy="-9.5701323711037E-09"
        ixz="3.88576084639882E-07"
        iyy="3.26053625381511E-05"
        iyz="-2.17344053344974E-07"
        izz="4.26350635605941E-05" />
    </inertial>
    <visual>
      <origin
        xyz="0 0 0"
        rpy="0 0 0" />
      <geometry>
        <mesh
          filename="package://++URDF_2.0/meshes/bl_hip.STL" />
      </geometry>
      <material
        name="">
        <color
          rgba="1 1 1 1" />
      </material>
    </visual>
    <collision>
      <origin
        xyz="0 0 0"
        rpy="0 0 0" />
      <geometry>
        <mesh
          filename="package://++URDF_2.0/meshes/bl_hip.STL" />
      </geometry>
    </collision>
  </link>
  <joint
    name="bl_hip"
    type="continuous">
    <origin
      xyz="-0.0984 -0.00302922105364486 -0.0606811932633948"
      rpy="0 0 0" />
    <parent
      link="base_link" />
    <child
      link="bl_hip" />
    <axis
      xyz="-1 0 0" />
  </joint>
  <link
    name="bl_top">
    <inertial>
      <origin
        xyz="-0.0332919917737501 -0.011761405740684 0.00583145711228228"
        rpy="0 0 0" />
      <mass
        value="0.139807399049" />
      <inertia
        ixx="3.21840569388915E-05"
        ixy="-4.4543175426684E-05"
        ixz="3.65621400096591E-07"
        iyy="0.000129862688192871"
        iyz="4.73135842246663E-07"
        izz="0.000148922342306775" />
    </inertial>
    <visual>
      <origin
        xyz="0 0 0"
        rpy="0 0 0" />
      <geometry>
        <mesh
          filename="package://++URDF_2.0/meshes/bl_top.STL" />
      </geometry>
      <material
        name="">
        <color
          rgba="1 1 1 1" />
      </material>
    </visual>
    <collision>
      <origin
        xyz="0 0 0"
        rpy="0 0 0" />
      <geometry>
        <mesh
          filename="package://++URDF_2.0/meshes/bl_top.STL" />
      </geometry>
    </collision>
  </link>
  <joint
    name="bl_top"
    type="continuous">
    <origin
      xyz="-0.0181000000001183 -0.0103448839199625 -0.0326150789771615"
      rpy="0 0 0" />
    <parent
      link="bl_hip" />
    <child
      link="bl_top" />
    <axis
      xyz="0 0.0201506967677564 -0.999796954096067" />
  </joint>
  <link
    name="bl_bottom">
    <inertial>
      <origin
        xyz="0.0817269974185858 -0.0387448949191614 0.00203600565191642"
        rpy="0 0 0" />
      <mass
        value="0.0474313022831092" />
      <inertia
        ixx="2.07936948016118E-05"
        ixy="3.29061979419239E-05"
        ixz="6.63457157491477E-07"
        iyy="6.62449710559728E-05"
        iyz="-3.69511557204602E-07"
        izz="8.45647068879262E-05" />
    </inertial>
    <visual>
      <origin
        xyz="0 0 0"
        rpy="0 0 0" />
      <geometry>
        <mesh
          filename="package://++URDF_2.0/meshes/bl_bottom.STL" />
      </geometry>
      <material
        name="">
        <color
          rgba="1 1 1 1" />
      </material>
    </visual>
    <collision>
      <origin
        xyz="0 0 0"
        rpy="0 0 0" />
      <geometry>
        <mesh
          filename="package://++URDF_2.0/meshes/bl_bottom.STL" />
      </geometry>
    </collision>
  </link>
  <joint
    name="bl_bottom"
    type="continuous">
    <origin
      xyz="-0.124595939429202 -0.0660533751871663 -0.0159842670738399"
      rpy="0 0 0" />
    <parent
      link="bl_top" />
    <child
      link="bl_bottom" />
    <axis
      xyz="0 0.0201506967677544 -0.999796954096068" />
  </joint>
</robot>